[2022-12-29 16:49:50,177] [autoreload.py:637] [autoreload:run_with_reloader] [INFO]- Watching for file changes with StatReloader
[2022-12-29 16:50:04,084] [basehttp.py:161] [basehttp:log_message] [INFO]- "GET / HTTP/1.1" 200 10137
[2022-12-29 16:50:04,882] [log.py:224] [log:log_response] [ERROR]- Internal Server Error: /api/count
Traceback (most recent call last):
  File "F:\DevProject\master\pic-slic-master\venv\lib\site-packages\django\core\handlers\exception.py", line 47, in inner
    response = get_response(request)
  File "F:\DevProject\master\pic-slic-master\venv\lib\site-packages\django\core\handlers\base.py", line 181, in _get_response
    response = wrapped_callback(request, *callback_args, **callback_kwargs)
  File "F:\DevProject\master\pic-slic-master\wxcloudrun\views.py", line 31, in counter
    rsp = get_count()
  File "F:\DevProject\master\pic-slic-master\wxcloudrun\views.py", line 47, in get_count
    data = Counters.objects.get(id=1)
  File "F:\DevProject\master\pic-slic-master\venv\lib\site-packages\django\db\models\manager.py", line 85, in manager_method
    return getattr(self.get_queryset(), name)(*args, **kwargs)
  File "F:\DevProject\master\pic-slic-master\venv\lib\site-packages\django\db\models\query.py", line 431, in get
    num = len(clone)
  File "F:\DevProject\master\pic-slic-master\venv\lib\site-packages\django\db\models\query.py", line 262, in __len__
    self._fetch_all()
  File "F:\DevProject\master\pic-slic-master\venv\lib\site-packages\django\db\models\query.py", line 1324, in _fetch_all
    self._result_cache = list(self._iterable_class(self))
  File "F:\DevProject\master\pic-slic-master\venv\lib\site-packages\django\db\models\query.py", line 51, in __iter__
    results = compiler.execute_sql(chunked_fetch=self.chunked_fetch, chunk_size=self.chunk_size)
  File "F:\DevProject\master\pic-slic-master\venv\lib\site-packages\django\db\models\sql\compiler.py", line 1162, in execute_sql
    sql, params = self.as_sql()
  File "F:\DevProject\master\pic-slic-master\venv\lib\site-packages\django\db\models\sql\compiler.py", line 513, in as_sql
    extra_select, order_by, group_by = self.pre_sql_setup()
  File "F:\DevProject\master\pic-slic-master\venv\lib\site-packages\django\db\models\sql\compiler.py", line 55, in pre_sql_setup
    self.setup_query()
  File "F:\DevProject\master\pic-slic-master\venv\lib\site-packages\django\db\models\sql\compiler.py", line 46, in setup_query
    self.select, self.klass_info, self.annotation_col_map = self.get_select()
  File "F:\DevProject\master\pic-slic-master\venv\lib\site-packages\django\db\models\sql\compiler.py", line 262, in get_select
    sql, params = self.compile(col)
  File "F:\DevProject\master\pic-slic-master\venv\lib\site-packages\django\db\models\sql\compiler.py", line 445, in compile
    sql, params = node.as_sql(self, self.connection)
  File "F:\DevProject\master\pic-slic-master\venv\lib\site-packages\django\db\models\expressions.py", line 835, in as_sql
    sql = '.'.join(map(compiler.quote_name_unless_alias, identifiers))
  File "F:\DevProject\master\pic-slic-master\venv\lib\site-packages\django\db\models\sql\compiler.py", line 436, in quote_name_unless_alias
    r = self.connection.ops.quote_name(name)
  File "F:\DevProject\master\pic-slic-master\venv\lib\site-packages\django\db\backends\dummy\base.py", line 20, in complain
    raise ImproperlyConfigured("settings.DATABASES is improperly configured. "
django.core.exceptions.ImproperlyConfigured: settings.DATABASES is improperly configured. Please supply the ENGINE value. Check settings documentation for more details.
[2022-12-29 16:50:04,885] [basehttp.py:161] [basehttp:log_message] [ERROR]- "GET /api/count HTTP/1.1" 500 131039
[2022-12-29 16:51:07,088] [views.py:62] [views:update_count] [INFO]- update_count req: b'{"action":"inc"}'
[2022-12-29 16:51:07,119] [log.py:224] [log:log_response] [ERROR]- Internal Server Error: /api/count
Traceback (most recent call last):
  File "F:\DevProject\master\pic-slic-master\venv\lib\site-packages\django\core\handlers\exception.py", line 47, in inner
    response = get_response(request)
  File "F:\DevProject\master\pic-slic-master\venv\lib\site-packages\django\core\handlers\base.py", line 181, in _get_response
    response = wrapped_callback(request, *callback_args, **callback_kwargs)
  File "F:\DevProject\master\pic-slic-master\wxcloudrun\views.py", line 33, in counter
    rsp = update_count(request)
  File "F:\DevProject\master\pic-slic-master\wxcloudrun\views.py", line 73, in update_count
    data = Counters.objects.get(id=1)
  File "F:\DevProject\master\pic-slic-master\venv\lib\site-packages\django\db\models\manager.py", line 85, in manager_method
    return getattr(self.get_queryset(), name)(*args, **kwargs)
  File "F:\DevProject\master\pic-slic-master\venv\lib\site-packages\django\db\models\query.py", line 431, in get
    num = len(clone)
  File "F:\DevProject\master\pic-slic-master\venv\lib\site-packages\django\db\models\query.py", line 262, in __len__
    self._fetch_all()
  File "F:\DevProject\master\pic-slic-master\venv\lib\site-packages\django\db\models\query.py", line 1324, in _fetch_all
    self._result_cache = list(self._iterable_class(self))
  File "F:\DevProject\master\pic-slic-master\venv\lib\site-packages\django\db\models\query.py", line 51, in __iter__
    results = compiler.execute_sql(chunked_fetch=self.chunked_fetch, chunk_size=self.chunk_size)
  File "F:\DevProject\master\pic-slic-master\venv\lib\site-packages\django\db\models\sql\compiler.py", line 1162, in execute_sql
    sql, params = self.as_sql()
  File "F:\DevProject\master\pic-slic-master\venv\lib\site-packages\django\db\models\sql\compiler.py", line 513, in as_sql
    extra_select, order_by, group_by = self.pre_sql_setup()
  File "F:\DevProject\master\pic-slic-master\venv\lib\site-packages\django\db\models\sql\compiler.py", line 55, in pre_sql_setup
    self.setup_query()
  File "F:\DevProject\master\pic-slic-master\venv\lib\site-packages\django\db\models\sql\compiler.py", line 46, in setup_query
    self.select, self.klass_info, self.annotation_col_map = self.get_select()
  File "F:\DevProject\master\pic-slic-master\venv\lib\site-packages\django\db\models\sql\compiler.py", line 262, in get_select
    sql, params = self.compile(col)
  File "F:\DevProject\master\pic-slic-master\venv\lib\site-packages\django\db\models\sql\compiler.py", line 445, in compile
    sql, params = node.as_sql(self, self.connection)
  File "F:\DevProject\master\pic-slic-master\venv\lib\site-packages\django\db\models\expressions.py", line 835, in as_sql
    sql = '.'.join(map(compiler.quote_name_unless_alias, identifiers))
  File "F:\DevProject\master\pic-slic-master\venv\lib\site-packages\django\db\models\sql\compiler.py", line 436, in quote_name_unless_alias
    r = self.connection.ops.quote_name(name)
  File "F:\DevProject\master\pic-slic-master\venv\lib\site-packages\django\db\backends\dummy\base.py", line 20, in complain
    raise ImproperlyConfigured("settings.DATABASES is improperly configured. "
django.core.exceptions.ImproperlyConfigured: settings.DATABASES is improperly configured. Please supply the ENGINE value. Check settings documentation for more details.
[2022-12-29 16:51:07,120] [basehttp.py:161] [basehttp:log_message] [ERROR]- "POST /api/count HTTP/1.1" 500 132451
[2022-12-29 16:51:08,363] [views.py:62] [views:update_count] [INFO]- update_count req: b'{"action":"inc"}'
[2022-12-29 16:51:08,391] [log.py:224] [log:log_response] [ERROR]- Internal Server Error: /api/count
Traceback (most recent call last):
  File "F:\DevProject\master\pic-slic-master\venv\lib\site-packages\django\core\handlers\exception.py", line 47, in inner
    response = get_response(request)
  File "F:\DevProject\master\pic-slic-master\venv\lib\site-packages\django\core\handlers\base.py", line 181, in _get_response
    response = wrapped_callback(request, *callback_args, **callback_kwargs)
  File "F:\DevProject\master\pic-slic-master\wxcloudrun\views.py", line 33, in counter
    rsp = update_count(request)
  File "F:\DevProject\master\pic-slic-master\wxcloudrun\views.py", line 73, in update_count
    data = Counters.objects.get(id=1)
  File "F:\DevProject\master\pic-slic-master\venv\lib\site-packages\django\db\models\manager.py", line 85, in manager_method
    return getattr(self.get_queryset(), name)(*args, **kwargs)
  File "F:\DevProject\master\pic-slic-master\venv\lib\site-packages\django\db\models\query.py", line 431, in get
    num = len(clone)
  File "F:\DevProject\master\pic-slic-master\venv\lib\site-packages\django\db\models\query.py", line 262, in __len__
    self._fetch_all()
  File "F:\DevProject\master\pic-slic-master\venv\lib\site-packages\django\db\models\query.py", line 1324, in _fetch_all
    self._result_cache = list(self._iterable_class(self))
  File "F:\DevProject\master\pic-slic-master\venv\lib\site-packages\django\db\models\query.py", line 51, in __iter__
    results = compiler.execute_sql(chunked_fetch=self.chunked_fetch, chunk_size=self.chunk_size)
  File "F:\DevProject\master\pic-slic-master\venv\lib\site-packages\django\db\models\sql\compiler.py", line 1162, in execute_sql
    sql, params = self.as_sql()
  File "F:\DevProject\master\pic-slic-master\venv\lib\site-packages\django\db\models\sql\compiler.py", line 513, in as_sql
    extra_select, order_by, group_by = self.pre_sql_setup()
  File "F:\DevProject\master\pic-slic-master\venv\lib\site-packages\django\db\models\sql\compiler.py", line 55, in pre_sql_setup
    self.setup_query()
  File "F:\DevProject\master\pic-slic-master\venv\lib\site-packages\django\db\models\sql\compiler.py", line 46, in setup_query
    self.select, self.klass_info, self.annotation_col_map = self.get_select()
  File "F:\DevProject\master\pic-slic-master\venv\lib\site-packages\django\db\models\sql\compiler.py", line 262, in get_select
    sql, params = self.compile(col)
  File "F:\DevProject\master\pic-slic-master\venv\lib\site-packages\django\db\models\sql\compiler.py", line 445, in compile
    sql, params = node.as_sql(self, self.connection)
  File "F:\DevProject\master\pic-slic-master\venv\lib\site-packages\django\db\models\expressions.py", line 835, in as_sql
    sql = '.'.join(map(compiler.quote_name_unless_alias, identifiers))
  File "F:\DevProject\master\pic-slic-master\venv\lib\site-packages\django\db\models\sql\compiler.py", line 436, in quote_name_unless_alias
    r = self.connection.ops.quote_name(name)
  File "F:\DevProject\master\pic-slic-master\venv\lib\site-packages\django\db\backends\dummy\base.py", line 20, in complain
    raise ImproperlyConfigured("settings.DATABASES is improperly configured. "
django.core.exceptions.ImproperlyConfigured: settings.DATABASES is improperly configured. Please supply the ENGINE value. Check settings documentation for more details.
[2022-12-29 16:51:08,392] [basehttp.py:161] [basehttp:log_message] [ERROR]- "POST /api/count HTTP/1.1" 500 132451
[2022-12-29 19:24:59,551] [autoreload.py:637] [autoreload:run_with_reloader] [INFO]- Watching for file changes with StatReloader
[2022-12-29 19:25:20,442] [basehttp.py:161] [basehttp:log_message] [INFO]- "GET /img HTTP/1.1" 200 10137
[2022-12-29 19:25:20,988] [log.py:224] [log:log_response] [ERROR]- Internal Server Error: /api/count
Traceback (most recent call last):
  File "F:\DevProject\master\pic-slic-master\venv\lib\site-packages\django\core\handlers\exception.py", line 47, in inner
    response = get_response(request)
  File "F:\DevProject\master\pic-slic-master\venv\lib\site-packages\django\core\handlers\base.py", line 181, in _get_response
    response = wrapped_callback(request, *callback_args, **callback_kwargs)
  File "F:\DevProject\master\pic-slic-master\wxcloudrun\views.py", line 41, in counter
    rsp = get_count()
  File "F:\DevProject\master\pic-slic-master\wxcloudrun\views.py", line 57, in get_count
    data = Counters.objects.get(id=1)
  File "F:\DevProject\master\pic-slic-master\venv\lib\site-packages\django\db\models\manager.py", line 85, in manager_method
    return getattr(self.get_queryset(), name)(*args, **kwargs)
  File "F:\DevProject\master\pic-slic-master\venv\lib\site-packages\django\db\models\query.py", line 431, in get
    num = len(clone)
  File "F:\DevProject\master\pic-slic-master\venv\lib\site-packages\django\db\models\query.py", line 262, in __len__
    self._fetch_all()
  File "F:\DevProject\master\pic-slic-master\venv\lib\site-packages\django\db\models\query.py", line 1324, in _fetch_all
    self._result_cache = list(self._iterable_class(self))
  File "F:\DevProject\master\pic-slic-master\venv\lib\site-packages\django\db\models\query.py", line 51, in __iter__
    results = compiler.execute_sql(chunked_fetch=self.chunked_fetch, chunk_size=self.chunk_size)
  File "F:\DevProject\master\pic-slic-master\venv\lib\site-packages\django\db\models\sql\compiler.py", line 1162, in execute_sql
    sql, params = self.as_sql()
  File "F:\DevProject\master\pic-slic-master\venv\lib\site-packages\django\db\models\sql\compiler.py", line 513, in as_sql
    extra_select, order_by, group_by = self.pre_sql_setup()
  File "F:\DevProject\master\pic-slic-master\venv\lib\site-packages\django\db\models\sql\compiler.py", line 55, in pre_sql_setup
    self.setup_query()
  File "F:\DevProject\master\pic-slic-master\venv\lib\site-packages\django\db\models\sql\compiler.py", line 46, in setup_query
    self.select, self.klass_info, self.annotation_col_map = self.get_select()
  File "F:\DevProject\master\pic-slic-master\venv\lib\site-packages\django\db\models\sql\compiler.py", line 262, in get_select
    sql, params = self.compile(col)
  File "F:\DevProject\master\pic-slic-master\venv\lib\site-packages\django\db\models\sql\compiler.py", line 445, in compile
    sql, params = node.as_sql(self, self.connection)
  File "F:\DevProject\master\pic-slic-master\venv\lib\site-packages\django\db\models\expressions.py", line 835, in as_sql
    sql = '.'.join(map(compiler.quote_name_unless_alias, identifiers))
  File "F:\DevProject\master\pic-slic-master\venv\lib\site-packages\django\db\models\sql\compiler.py", line 436, in quote_name_unless_alias
    r = self.connection.ops.quote_name(name)
  File "F:\DevProject\master\pic-slic-master\venv\lib\site-packages\django\db\backends\dummy\base.py", line 20, in complain
    raise ImproperlyConfigured("settings.DATABASES is improperly configured. "
django.core.exceptions.ImproperlyConfigured: settings.DATABASES is improperly configured. Please supply the ENGINE value. Check settings documentation for more details.
[2022-12-29 19:25:20,990] [basehttp.py:161] [basehttp:log_message] [ERROR]- "GET /api/count HTTP/1.1" 500 131042
[2022-12-29 19:25:41,562] [log.py:224] [log:log_response] [ERROR]- Internal Server Error: /api/count
Traceback (most recent call last):
  File "F:\DevProject\master\pic-slic-master\venv\lib\site-packages\django\core\handlers\exception.py", line 47, in inner
    response = get_response(request)
  File "F:\DevProject\master\pic-slic-master\venv\lib\site-packages\django\core\handlers\base.py", line 181, in _get_response
    response = wrapped_callback(request, *callback_args, **callback_kwargs)
  File "F:\DevProject\master\pic-slic-master\wxcloudrun\views.py", line 41, in counter
    rsp = get_count()
  File "F:\DevProject\master\pic-slic-master\wxcloudrun\views.py", line 57, in get_count
    data = Counters.objects.get(id=1)
  File "F:\DevProject\master\pic-slic-master\venv\lib\site-packages\django\db\models\manager.py", line 85, in manager_method
    return getattr(self.get_queryset(), name)(*args, **kwargs)
  File "F:\DevProject\master\pic-slic-master\venv\lib\site-packages\django\db\models\query.py", line 431, in get
    num = len(clone)
  File "F:\DevProject\master\pic-slic-master\venv\lib\site-packages\django\db\models\query.py", line 262, in __len__
    self._fetch_all()
  File "F:\DevProject\master\pic-slic-master\venv\lib\site-packages\django\db\models\query.py", line 1324, in _fetch_all
    self._result_cache = list(self._iterable_class(self))
  File "F:\DevProject\master\pic-slic-master\venv\lib\site-packages\django\db\models\query.py", line 51, in __iter__
    results = compiler.execute_sql(chunked_fetch=self.chunked_fetch, chunk_size=self.chunk_size)
  File "F:\DevProject\master\pic-slic-master\venv\lib\site-packages\django\db\models\sql\compiler.py", line 1162, in execute_sql
    sql, params = self.as_sql()
  File "F:\DevProject\master\pic-slic-master\venv\lib\site-packages\django\db\models\sql\compiler.py", line 513, in as_sql
    extra_select, order_by, group_by = self.pre_sql_setup()
  File "F:\DevProject\master\pic-slic-master\venv\lib\site-packages\django\db\models\sql\compiler.py", line 55, in pre_sql_setup
    self.setup_query()
  File "F:\DevProject\master\pic-slic-master\venv\lib\site-packages\django\db\models\sql\compiler.py", line 46, in setup_query
    self.select, self.klass_info, self.annotation_col_map = self.get_select()
  File "F:\DevProject\master\pic-slic-master\venv\lib\site-packages\django\db\models\sql\compiler.py", line 262, in get_select
    sql, params = self.compile(col)
  File "F:\DevProject\master\pic-slic-master\venv\lib\site-packages\django\db\models\sql\compiler.py", line 445, in compile
    sql, params = node.as_sql(self, self.connection)
  File "F:\DevProject\master\pic-slic-master\venv\lib\site-packages\django\db\models\expressions.py", line 835, in as_sql
    sql = '.'.join(map(compiler.quote_name_unless_alias, identifiers))
  File "F:\DevProject\master\pic-slic-master\venv\lib\site-packages\django\db\models\sql\compiler.py", line 436, in quote_name_unless_alias
    r = self.connection.ops.quote_name(name)
  File "F:\DevProject\master\pic-slic-master\venv\lib\site-packages\django\db\backends\dummy\base.py", line 20, in complain
    raise ImproperlyConfigured("settings.DATABASES is improperly configured. "
django.core.exceptions.ImproperlyConfigured: settings.DATABASES is improperly configured. Please supply the ENGINE value. Check settings documentation for more details.
[2022-12-29 19:25:41,563] [basehttp.py:161] [basehttp:log_message] [ERROR]- "GET /api/count HTTP/1.1" 500 131154
[2022-12-29 19:25:41,805] [basehttp.py:161] [basehttp:log_message] [INFO]- "GET /favicon.ico HTTP/1.1" 200 10137
[2022-12-29 19:26:08,037] [basehttp.py:161] [basehttp:log_message] [INFO]- "GET /img HTTP/1.1" 200 10137
[2022-12-29 19:26:08,147] [log.py:224] [log:log_response] [ERROR]- Internal Server Error: /api/count
Traceback (most recent call last):
  File "F:\DevProject\master\pic-slic-master\venv\lib\site-packages\django\core\handlers\exception.py", line 47, in inner
    response = get_response(request)
  File "F:\DevProject\master\pic-slic-master\venv\lib\site-packages\django\core\handlers\base.py", line 181, in _get_response
    response = wrapped_callback(request, *callback_args, **callback_kwargs)
  File "F:\DevProject\master\pic-slic-master\wxcloudrun\views.py", line 41, in counter
    rsp = get_count()
  File "F:\DevProject\master\pic-slic-master\wxcloudrun\views.py", line 57, in get_count
    data = Counters.objects.get(id=1)
  File "F:\DevProject\master\pic-slic-master\venv\lib\site-packages\django\db\models\manager.py", line 85, in manager_method
    return getattr(self.get_queryset(), name)(*args, **kwargs)
  File "F:\DevProject\master\pic-slic-master\venv\lib\site-packages\django\db\models\query.py", line 431, in get
    num = len(clone)
  File "F:\DevProject\master\pic-slic-master\venv\lib\site-packages\django\db\models\query.py", line 262, in __len__
    self._fetch_all()
  File "F:\DevProject\master\pic-slic-master\venv\lib\site-packages\django\db\models\query.py", line 1324, in _fetch_all
    self._result_cache = list(self._iterable_class(self))
  File "F:\DevProject\master\pic-slic-master\venv\lib\site-packages\django\db\models\query.py", line 51, in __iter__
    results = compiler.execute_sql(chunked_fetch=self.chunked_fetch, chunk_size=self.chunk_size)
  File "F:\DevProject\master\pic-slic-master\venv\lib\site-packages\django\db\models\sql\compiler.py", line 1162, in execute_sql
    sql, params = self.as_sql()
  File "F:\DevProject\master\pic-slic-master\venv\lib\site-packages\django\db\models\sql\compiler.py", line 513, in as_sql
    extra_select, order_by, group_by = self.pre_sql_setup()
  File "F:\DevProject\master\pic-slic-master\venv\lib\site-packages\django\db\models\sql\compiler.py", line 55, in pre_sql_setup
    self.setup_query()
  File "F:\DevProject\master\pic-slic-master\venv\lib\site-packages\django\db\models\sql\compiler.py", line 46, in setup_query
    self.select, self.klass_info, self.annotation_col_map = self.get_select()
  File "F:\DevProject\master\pic-slic-master\venv\lib\site-packages\django\db\models\sql\compiler.py", line 262, in get_select
    sql, params = self.compile(col)
  File "F:\DevProject\master\pic-slic-master\venv\lib\site-packages\django\db\models\sql\compiler.py", line 445, in compile
    sql, params = node.as_sql(self, self.connection)
  File "F:\DevProject\master\pic-slic-master\venv\lib\site-packages\django\db\models\expressions.py", line 835, in as_sql
    sql = '.'.join(map(compiler.quote_name_unless_alias, identifiers))
  File "F:\DevProject\master\pic-slic-master\venv\lib\site-packages\django\db\models\sql\compiler.py", line 436, in quote_name_unless_alias
    r = self.connection.ops.quote_name(name)
  File "F:\DevProject\master\pic-slic-master\venv\lib\site-packages\django\db\backends\dummy\base.py", line 20, in complain
    raise ImproperlyConfigured("settings.DATABASES is improperly configured. "
django.core.exceptions.ImproperlyConfigured: settings.DATABASES is improperly configured. Please supply the ENGINE value. Check settings documentation for more details.
[2022-12-29 19:26:08,148] [basehttp.py:161] [basehttp:log_message] [ERROR]- "GET /api/count HTTP/1.1" 500 131042
[2022-12-29 19:26:31,791] [basehttp.py:161] [basehttp:log_message] [INFO]- "GET /img HTTP/1.1" 200 10137
[2022-12-29 19:26:31,883] [log.py:224] [log:log_response] [ERROR]- Internal Server Error: /api/count
Traceback (most recent call last):
  File "F:\DevProject\master\pic-slic-master\venv\lib\site-packages\django\core\handlers\exception.py", line 47, in inner
    response = get_response(request)
  File "F:\DevProject\master\pic-slic-master\venv\lib\site-packages\django\core\handlers\base.py", line 181, in _get_response
    response = wrapped_callback(request, *callback_args, **callback_kwargs)
  File "F:\DevProject\master\pic-slic-master\wxcloudrun\views.py", line 41, in counter
    rsp = get_count()
  File "F:\DevProject\master\pic-slic-master\wxcloudrun\views.py", line 57, in get_count
    data = Counters.objects.get(id=1)
  File "F:\DevProject\master\pic-slic-master\venv\lib\site-packages\django\db\models\manager.py", line 85, in manager_method
    return getattr(self.get_queryset(), name)(*args, **kwargs)
  File "F:\DevProject\master\pic-slic-master\venv\lib\site-packages\django\db\models\query.py", line 431, in get
    num = len(clone)
  File "F:\DevProject\master\pic-slic-master\venv\lib\site-packages\django\db\models\query.py", line 262, in __len__
    self._fetch_all()
  File "F:\DevProject\master\pic-slic-master\venv\lib\site-packages\django\db\models\query.py", line 1324, in _fetch_all
    self._result_cache = list(self._iterable_class(self))
  File "F:\DevProject\master\pic-slic-master\venv\lib\site-packages\django\db\models\query.py", line 51, in __iter__
    results = compiler.execute_sql(chunked_fetch=self.chunked_fetch, chunk_size=self.chunk_size)
  File "F:\DevProject\master\pic-slic-master\venv\lib\site-packages\django\db\models\sql\compiler.py", line 1162, in execute_sql
    sql, params = self.as_sql()
  File "F:\DevProject\master\pic-slic-master\venv\lib\site-packages\django\db\models\sql\compiler.py", line 513, in as_sql
    extra_select, order_by, group_by = self.pre_sql_setup()
  File "F:\DevProject\master\pic-slic-master\venv\lib\site-packages\django\db\models\sql\compiler.py", line 55, in pre_sql_setup
    self.setup_query()
  File "F:\DevProject\master\pic-slic-master\venv\lib\site-packages\django\db\models\sql\compiler.py", line 46, in setup_query
    self.select, self.klass_info, self.annotation_col_map = self.get_select()
  File "F:\DevProject\master\pic-slic-master\venv\lib\site-packages\django\db\models\sql\compiler.py", line 262, in get_select
    sql, params = self.compile(col)
  File "F:\DevProject\master\pic-slic-master\venv\lib\site-packages\django\db\models\sql\compiler.py", line 445, in compile
    sql, params = node.as_sql(self, self.connection)
  File "F:\DevProject\master\pic-slic-master\venv\lib\site-packages\django\db\models\expressions.py", line 835, in as_sql
    sql = '.'.join(map(compiler.quote_name_unless_alias, identifiers))
  File "F:\DevProject\master\pic-slic-master\venv\lib\site-packages\django\db\models\sql\compiler.py", line 436, in quote_name_unless_alias
    r = self.connection.ops.quote_name(name)
  File "F:\DevProject\master\pic-slic-master\venv\lib\site-packages\django\db\backends\dummy\base.py", line 20, in complain
    raise ImproperlyConfigured("settings.DATABASES is improperly configured. "
django.core.exceptions.ImproperlyConfigured: settings.DATABASES is improperly configured. Please supply the ENGINE value. Check settings documentation for more details.
[2022-12-29 19:26:31,884] [basehttp.py:161] [basehttp:log_message] [ERROR]- "GET /api/count HTTP/1.1" 500 131042
[2022-12-29 19:41:46,373] [autoreload.py:251] [autoreload:trigger_reload] [INFO]- F:\DevProject\master\pic-slic-master\wxcloudrun\urls.py changed, reloading.
[2022-12-29 19:41:47,047] [autoreload.py:637] [autoreload:run_with_reloader] [INFO]- Watching for file changes with StatReloader
[2022-12-29 19:42:14,082] [autoreload.py:251] [autoreload:trigger_reload] [INFO]- F:\DevProject\master\pic-slic-master\wxcloudrun\urls.py changed, reloading.
[2022-12-29 19:42:14,740] [autoreload.py:637] [autoreload:run_with_reloader] [INFO]- Watching for file changes with StatReloader
[2022-12-29 19:43:20,979] [autoreload.py:637] [autoreload:run_with_reloader] [INFO]- Watching for file changes with StatReloader
[2022-12-29 19:43:23,762] [basehttp.py:161] [basehttp:log_message] [INFO]- "GET /img HTTP/1.1" 200 10137
[2022-12-29 19:43:23,873] [log.py:224] [log:log_response] [ERROR]- Internal Server Error: /api/count
Traceback (most recent call last):
  File "F:\DevProject\master\pic-slic-master\venv\lib\site-packages\django\core\handlers\exception.py", line 47, in inner
    response = get_response(request)
  File "F:\DevProject\master\pic-slic-master\venv\lib\site-packages\django\core\handlers\base.py", line 181, in _get_response
    response = wrapped_callback(request, *callback_args, **callback_kwargs)
  File "F:\DevProject\master\pic-slic-master\wxcloudrun\views.py", line 41, in counter
    rsp = get_count()
  File "F:\DevProject\master\pic-slic-master\wxcloudrun\views.py", line 57, in get_count
    data = Counters.objects.get(id=1)
  File "F:\DevProject\master\pic-slic-master\venv\lib\site-packages\django\db\models\manager.py", line 85, in manager_method
    return getattr(self.get_queryset(), name)(*args, **kwargs)
  File "F:\DevProject\master\pic-slic-master\venv\lib\site-packages\django\db\models\query.py", line 431, in get
    num = len(clone)
  File "F:\DevProject\master\pic-slic-master\venv\lib\site-packages\django\db\models\query.py", line 262, in __len__
    self._fetch_all()
  File "F:\DevProject\master\pic-slic-master\venv\lib\site-packages\django\db\models\query.py", line 1324, in _fetch_all
    self._result_cache = list(self._iterable_class(self))
  File "F:\DevProject\master\pic-slic-master\venv\lib\site-packages\django\db\models\query.py", line 51, in __iter__
    results = compiler.execute_sql(chunked_fetch=self.chunked_fetch, chunk_size=self.chunk_size)
  File "F:\DevProject\master\pic-slic-master\venv\lib\site-packages\django\db\models\sql\compiler.py", line 1162, in execute_sql
    sql, params = self.as_sql()
  File "F:\DevProject\master\pic-slic-master\venv\lib\site-packages\django\db\models\sql\compiler.py", line 513, in as_sql
    extra_select, order_by, group_by = self.pre_sql_setup()
  File "F:\DevProject\master\pic-slic-master\venv\lib\site-packages\django\db\models\sql\compiler.py", line 55, in pre_sql_setup
    self.setup_query()
  File "F:\DevProject\master\pic-slic-master\venv\lib\site-packages\django\db\models\sql\compiler.py", line 46, in setup_query
    self.select, self.klass_info, self.annotation_col_map = self.get_select()
  File "F:\DevProject\master\pic-slic-master\venv\lib\site-packages\django\db\models\sql\compiler.py", line 262, in get_select
    sql, params = self.compile(col)
  File "F:\DevProject\master\pic-slic-master\venv\lib\site-packages\django\db\models\sql\compiler.py", line 445, in compile
    sql, params = node.as_sql(self, self.connection)
  File "F:\DevProject\master\pic-slic-master\venv\lib\site-packages\django\db\models\expressions.py", line 835, in as_sql
    sql = '.'.join(map(compiler.quote_name_unless_alias, identifiers))
  File "F:\DevProject\master\pic-slic-master\venv\lib\site-packages\django\db\models\sql\compiler.py", line 436, in quote_name_unless_alias
    r = self.connection.ops.quote_name(name)
  File "F:\DevProject\master\pic-slic-master\venv\lib\site-packages\django\db\backends\dummy\base.py", line 20, in complain
    raise ImproperlyConfigured("settings.DATABASES is improperly configured. "
django.core.exceptions.ImproperlyConfigured: settings.DATABASES is improperly configured. Please supply the ENGINE value. Check settings documentation for more details.
[2022-12-29 19:43:23,875] [basehttp.py:161] [basehttp:log_message] [ERROR]- "GET /api/count HTTP/1.1" 500 131042
[2022-12-29 19:44:59,831] [autoreload.py:637] [autoreload:run_with_reloader] [INFO]- Watching for file changes with StatReloader
[2022-12-29 19:45:13,387] [basehttp.py:161] [basehttp:log_message] [INFO]- "GET / HTTP/1.1" 200 1043
[2022-12-29 19:45:13,567] [basehttp.py:161] [basehttp:log_message] [INFO]- "GET /favicon.ico HTTP/1.1" 200 1043
[2022-12-29 19:45:36,043] [autoreload.py:637] [autoreload:run_with_reloader] [INFO]- Watching for file changes with StatReloader
[2022-12-29 19:45:39,416] [basehttp.py:161] [basehttp:log_message] [INFO]- "GET / HTTP/1.1" 200 1043
[2022-12-29 19:45:39,581] [basehttp.py:161] [basehttp:log_message] [INFO]- "GET /favicon.ico HTTP/1.1" 200 1043
[2022-12-29 19:45:45,928] [basehttp.py:161] [basehttp:log_message] [INFO]- "GET /img HTTP/1.1" 200 1043
[2022-12-29 19:45:46,102] [basehttp.py:161] [basehttp:log_message] [INFO]- "GET /favicon.ico HTTP/1.1" 200 1043
[2022-12-29 19:46:18,978] [autoreload.py:637] [autoreload:run_with_reloader] [INFO]- Watching for file changes with StatReloader
[2022-12-29 19:46:25,625] [basehttp.py:161] [basehttp:log_message] [INFO]- "GET / HTTP/1.1" 200 1043
[2022-12-29 19:46:25,823] [basehttp.py:161] [basehttp:log_message] [INFO]- "GET /favicon.ico HTTP/1.1" 200 1043
[2022-12-29 19:46:59,043] [basehttp.py:161] [basehttp:log_message] [INFO]- "GET / HTTP/1.1" 200 1043
[2022-12-29 19:46:59,207] [basehttp.py:161] [basehttp:log_message] [INFO]- "GET /favicon.ico HTTP/1.1" 200 1043
[2022-12-29 19:47:26,512] [basehttp.py:161] [basehttp:log_message] [INFO]- "GET / HTTP/1.1" 200 1043
[2022-12-29 19:47:26,682] [basehttp.py:161] [basehttp:log_message] [INFO]- "GET /favicon.ico HTTP/1.1" 200 1043
[2022-12-29 19:48:02,534] [autoreload.py:637] [autoreload:run_with_reloader] [INFO]- Watching for file changes with StatReloader
[2022-12-29 19:48:05,172] [basehttp.py:161] [basehttp:log_message] [INFO]- "GET / HTTP/1.1" 200 10137
[2022-12-29 19:48:05,717] [log.py:224] [log:log_response] [ERROR]- Internal Server Error: /api/count
Traceback (most recent call last):
  File "F:\DevProject\master\pic-slic-master\venv\lib\site-packages\django\core\handlers\exception.py", line 47, in inner
    response = get_response(request)
  File "F:\DevProject\master\pic-slic-master\venv\lib\site-packages\django\core\handlers\base.py", line 181, in _get_response
    response = wrapped_callback(request, *callback_args, **callback_kwargs)
  File "F:\DevProject\master\pic-slic-master\wxcloudrun\views.py", line 41, in counter
    rsp = get_count()
  File "F:\DevProject\master\pic-slic-master\wxcloudrun\views.py", line 57, in get_count
    data = Counters.objects.get(id=1)
  File "F:\DevProject\master\pic-slic-master\venv\lib\site-packages\django\db\models\manager.py", line 85, in manager_method
    return getattr(self.get_queryset(), name)(*args, **kwargs)
  File "F:\DevProject\master\pic-slic-master\venv\lib\site-packages\django\db\models\query.py", line 431, in get
    num = len(clone)
  File "F:\DevProject\master\pic-slic-master\venv\lib\site-packages\django\db\models\query.py", line 262, in __len__
    self._fetch_all()
  File "F:\DevProject\master\pic-slic-master\venv\lib\site-packages\django\db\models\query.py", line 1324, in _fetch_all
    self._result_cache = list(self._iterable_class(self))
  File "F:\DevProject\master\pic-slic-master\venv\lib\site-packages\django\db\models\query.py", line 51, in __iter__
    results = compiler.execute_sql(chunked_fetch=self.chunked_fetch, chunk_size=self.chunk_size)
  File "F:\DevProject\master\pic-slic-master\venv\lib\site-packages\django\db\models\sql\compiler.py", line 1162, in execute_sql
    sql, params = self.as_sql()
  File "F:\DevProject\master\pic-slic-master\venv\lib\site-packages\django\db\models\sql\compiler.py", line 513, in as_sql
    extra_select, order_by, group_by = self.pre_sql_setup()
  File "F:\DevProject\master\pic-slic-master\venv\lib\site-packages\django\db\models\sql\compiler.py", line 55, in pre_sql_setup
    self.setup_query()
  File "F:\DevProject\master\pic-slic-master\venv\lib\site-packages\django\db\models\sql\compiler.py", line 46, in setup_query
    self.select, self.klass_info, self.annotation_col_map = self.get_select()
  File "F:\DevProject\master\pic-slic-master\venv\lib\site-packages\django\db\models\sql\compiler.py", line 262, in get_select
    sql, params = self.compile(col)
  File "F:\DevProject\master\pic-slic-master\venv\lib\site-packages\django\db\models\sql\compiler.py", line 445, in compile
    sql, params = node.as_sql(self, self.connection)
  File "F:\DevProject\master\pic-slic-master\venv\lib\site-packages\django\db\models\expressions.py", line 835, in as_sql
    sql = '.'.join(map(compiler.quote_name_unless_alias, identifiers))
  File "F:\DevProject\master\pic-slic-master\venv\lib\site-packages\django\db\models\sql\compiler.py", line 436, in quote_name_unless_alias
    r = self.connection.ops.quote_name(name)
  File "F:\DevProject\master\pic-slic-master\venv\lib\site-packages\django\db\backends\dummy\base.py", line 20, in complain
    raise ImproperlyConfigured("settings.DATABASES is improperly configured. "
django.core.exceptions.ImproperlyConfigured: settings.DATABASES is improperly configured. Please supply the ENGINE value. Check settings documentation for more details.
[2022-12-29 19:48:05,719] [basehttp.py:161] [basehttp:log_message] [ERROR]- "GET /api/count HTTP/1.1" 500 130548
[2022-12-29 19:48:15,872] [basehttp.py:161] [basehttp:log_message] [INFO]- "GET /img HTTP/1.1" 200 10137
[2022-12-29 19:48:16,021] [log.py:224] [log:log_response] [ERROR]- Internal Server Error: /api/count
Traceback (most recent call last):
  File "F:\DevProject\master\pic-slic-master\venv\lib\site-packages\django\core\handlers\exception.py", line 47, in inner
    response = get_response(request)
  File "F:\DevProject\master\pic-slic-master\venv\lib\site-packages\django\core\handlers\base.py", line 181, in _get_response
    response = wrapped_callback(request, *callback_args, **callback_kwargs)
  File "F:\DevProject\master\pic-slic-master\wxcloudrun\views.py", line 41, in counter
    rsp = get_count()
  File "F:\DevProject\master\pic-slic-master\wxcloudrun\views.py", line 57, in get_count
    data = Counters.objects.get(id=1)
  File "F:\DevProject\master\pic-slic-master\venv\lib\site-packages\django\db\models\manager.py", line 85, in manager_method
    return getattr(self.get_queryset(), name)(*args, **kwargs)
  File "F:\DevProject\master\pic-slic-master\venv\lib\site-packages\django\db\models\query.py", line 431, in get
    num = len(clone)
  File "F:\DevProject\master\pic-slic-master\venv\lib\site-packages\django\db\models\query.py", line 262, in __len__
    self._fetch_all()
  File "F:\DevProject\master\pic-slic-master\venv\lib\site-packages\django\db\models\query.py", line 1324, in _fetch_all
    self._result_cache = list(self._iterable_class(self))
  File "F:\DevProject\master\pic-slic-master\venv\lib\site-packages\django\db\models\query.py", line 51, in __iter__
    results = compiler.execute_sql(chunked_fetch=self.chunked_fetch, chunk_size=self.chunk_size)
  File "F:\DevProject\master\pic-slic-master\venv\lib\site-packages\django\db\models\sql\compiler.py", line 1162, in execute_sql
    sql, params = self.as_sql()
  File "F:\DevProject\master\pic-slic-master\venv\lib\site-packages\django\db\models\sql\compiler.py", line 513, in as_sql
    extra_select, order_by, group_by = self.pre_sql_setup()
  File "F:\DevProject\master\pic-slic-master\venv\lib\site-packages\django\db\models\sql\compiler.py", line 55, in pre_sql_setup
    self.setup_query()
  File "F:\DevProject\master\pic-slic-master\venv\lib\site-packages\django\db\models\sql\compiler.py", line 46, in setup_query
    self.select, self.klass_info, self.annotation_col_map = self.get_select()
  File "F:\DevProject\master\pic-slic-master\venv\lib\site-packages\django\db\models\sql\compiler.py", line 262, in get_select
    sql, params = self.compile(col)
  File "F:\DevProject\master\pic-slic-master\venv\lib\site-packages\django\db\models\sql\compiler.py", line 445, in compile
    sql, params = node.as_sql(self, self.connection)
  File "F:\DevProject\master\pic-slic-master\venv\lib\site-packages\django\db\models\expressions.py", line 835, in as_sql
    sql = '.'.join(map(compiler.quote_name_unless_alias, identifiers))
  File "F:\DevProject\master\pic-slic-master\venv\lib\site-packages\django\db\models\sql\compiler.py", line 436, in quote_name_unless_alias
    r = self.connection.ops.quote_name(name)
  File "F:\DevProject\master\pic-slic-master\venv\lib\site-packages\django\db\backends\dummy\base.py", line 20, in complain
    raise ImproperlyConfigured("settings.DATABASES is improperly configured. "
django.core.exceptions.ImproperlyConfigured: settings.DATABASES is improperly configured. Please supply the ENGINE value. Check settings documentation for more details.
[2022-12-29 19:48:16,023] [basehttp.py:161] [basehttp:log_message] [ERROR]- "GET /api/count HTTP/1.1" 500 130551
[2022-12-29 19:49:45,447] [autoreload.py:637] [autoreload:run_with_reloader] [INFO]- Watching for file changes with StatReloader
[2022-12-29 19:49:48,727] [basehttp.py:161] [basehttp:log_message] [INFO]- "GET /img HTTP/1.1" 200 10137
[2022-12-29 19:49:48,845] [log.py:224] [log:log_response] [ERROR]- Internal Server Error: /api/count
Traceback (most recent call last):
  File "F:\DevProject\master\pic-slic-master\venv\lib\site-packages\django\core\handlers\exception.py", line 47, in inner
    response = get_response(request)
  File "F:\DevProject\master\pic-slic-master\venv\lib\site-packages\django\core\handlers\base.py", line 181, in _get_response
    response = wrapped_callback(request, *callback_args, **callback_kwargs)
  File "F:\DevProject\master\pic-slic-master\wxcloudrun\views.py", line 41, in counter
    rsp = get_count()
  File "F:\DevProject\master\pic-slic-master\wxcloudrun\views.py", line 57, in get_count
    data = Counters.objects.get(id=1)
  File "F:\DevProject\master\pic-slic-master\venv\lib\site-packages\django\db\models\manager.py", line 85, in manager_method
    return getattr(self.get_queryset(), name)(*args, **kwargs)
  File "F:\DevProject\master\pic-slic-master\venv\lib\site-packages\django\db\models\query.py", line 431, in get
    num = len(clone)
  File "F:\DevProject\master\pic-slic-master\venv\lib\site-packages\django\db\models\query.py", line 262, in __len__
    self._fetch_all()
  File "F:\DevProject\master\pic-slic-master\venv\lib\site-packages\django\db\models\query.py", line 1324, in _fetch_all
    self._result_cache = list(self._iterable_class(self))
  File "F:\DevProject\master\pic-slic-master\venv\lib\site-packages\django\db\models\query.py", line 51, in __iter__
    results = compiler.execute_sql(chunked_fetch=self.chunked_fetch, chunk_size=self.chunk_size)
  File "F:\DevProject\master\pic-slic-master\venv\lib\site-packages\django\db\models\sql\compiler.py", line 1162, in execute_sql
    sql, params = self.as_sql()
  File "F:\DevProject\master\pic-slic-master\venv\lib\site-packages\django\db\models\sql\compiler.py", line 513, in as_sql
    extra_select, order_by, group_by = self.pre_sql_setup()
  File "F:\DevProject\master\pic-slic-master\venv\lib\site-packages\django\db\models\sql\compiler.py", line 55, in pre_sql_setup
    self.setup_query()
  File "F:\DevProject\master\pic-slic-master\venv\lib\site-packages\django\db\models\sql\compiler.py", line 46, in setup_query
    self.select, self.klass_info, self.annotation_col_map = self.get_select()
  File "F:\DevProject\master\pic-slic-master\venv\lib\site-packages\django\db\models\sql\compiler.py", line 262, in get_select
    sql, params = self.compile(col)
  File "F:\DevProject\master\pic-slic-master\venv\lib\site-packages\django\db\models\sql\compiler.py", line 445, in compile
    sql, params = node.as_sql(self, self.connection)
  File "F:\DevProject\master\pic-slic-master\venv\lib\site-packages\django\db\models\expressions.py", line 835, in as_sql
    sql = '.'.join(map(compiler.quote_name_unless_alias, identifiers))
  File "F:\DevProject\master\pic-slic-master\venv\lib\site-packages\django\db\models\sql\compiler.py", line 436, in quote_name_unless_alias
    r = self.connection.ops.quote_name(name)
  File "F:\DevProject\master\pic-slic-master\venv\lib\site-packages\django\db\backends\dummy\base.py", line 20, in complain
    raise ImproperlyConfigured("settings.DATABASES is improperly configured. "
django.core.exceptions.ImproperlyConfigured: settings.DATABASES is improperly configured. Please supply the ENGINE value. Check settings documentation for more details.
[2022-12-29 19:49:48,849] [basehttp.py:161] [basehttp:log_message] [ERROR]- "GET /api/count HTTP/1.1" 500 130551
[2022-12-29 19:52:43,093] [autoreload.py:251] [autoreload:trigger_reload] [INFO]- F:\DevProject\master\pic-slic-master\wxcloudrun\urls.py changed, reloading.
[2022-12-29 19:52:43,700] [autoreload.py:637] [autoreload:run_with_reloader] [INFO]- Watching for file changes with StatReloader
[2022-12-29 19:53:14,829] [autoreload.py:637] [autoreload:run_with_reloader] [INFO]- Watching for file changes with StatReloader
[2022-12-29 19:53:19,682] [basehttp.py:161] [basehttp:log_message] [INFO]- "GET /img HTTP/1.1" 301 0
[2022-12-29 19:53:19,714] [log.py:224] [log:log_response] [ERROR]- Internal Server Error: /img/
Traceback (most recent call last):
  File "F:\DevProject\master\pic-slic-master\venv\lib\site-packages\django\core\handlers\exception.py", line 47, in inner
    response = get_response(request)
  File "F:\DevProject\master\pic-slic-master\venv\lib\site-packages\django\core\handlers\base.py", line 181, in _get_response
    response = wrapped_callback(request, *callback_args, **callback_kwargs)
TypeError: img() missing 1 required positional argument: '_'
[2022-12-29 19:53:19,715] [basehttp.py:161] [basehttp:log_message] [ERROR]- "GET /img/ HTTP/1.1" 500 62850
[2022-12-29 19:53:19,999] [log.py:224] [log:log_response] [WARNING]- Not Found: /favicon.ico
[2022-12-29 19:53:20,000] [basehttp.py:161] [basehttp:log_message] [WARNING]- "GET /favicon.ico HTTP/1.1" 404 2227
[2022-12-29 19:54:34,288] [autoreload.py:637] [autoreload:run_with_reloader] [INFO]- Watching for file changes with StatReloader
[2022-12-29 19:54:36,580] [basehttp.py:161] [basehttp:log_message] [INFO]- "GET /img/ HTTP/1.1" 200 1043
[2022-12-29 19:55:22,654] [autoreload.py:637] [autoreload:run_with_reloader] [INFO]- Watching for file changes with StatReloader
[2022-12-29 19:55:23,862] [basehttp.py:161] [basehttp:log_message] [INFO]- "GET /img/ HTTP/1.1" 200 1043
[2022-12-29 19:55:26,705] [basehttp.py:161] [basehttp:log_message] [INFO]- "GET /img/ HTTP/1.1" 200 1043
[2022-12-29 19:56:08,605] [autoreload.py:637] [autoreload:run_with_reloader] [INFO]- Watching for file changes with StatReloader
[2022-12-29 19:56:10,952] [basehttp.py:161] [basehttp:log_message] [INFO]- "GET /img/ HTTP/1.1" 200 1043
[2022-12-29 19:58:01,117] [basehttp.py:161] [basehttp:log_message] [INFO]- "GET /img/ HTTP/1.1" 200 1043
[2022-12-29 20:02:40,366] [log.py:224] [log:log_response] [ERROR]- Internal Server Error: /api/img/
Traceback (most recent call last):
  File "F:\DevProject\master\pic-slic-master\venv\lib\site-packages\django\core\handlers\exception.py", line 47, in inner
    response = get_response(request)
  File "F:\DevProject\master\pic-slic-master\venv\lib\site-packages\django\core\handlers\base.py", line 181, in _get_response
    response = wrapped_callback(request, *callback_args, **callback_kwargs)
TypeError: test_pro() takes 0 positional arguments but 1 was given
[2022-12-29 20:02:40,367] [basehttp.py:161] [basehttp:log_message] [ERROR]- "GET /api/img/ HTTP/1.1" 500 62743
[2022-12-29 20:06:53,393] [autoreload.py:637] [autoreload:run_with_reloader] [INFO]- Watching for file changes with StatReloader
[2022-12-29 20:06:57,792] [log.py:224] [log:log_response] [ERROR]- Internal Server Error: /api/img/
Traceback (most recent call last):
  File "F:\DevProject\master\pic-slic-master\venv\lib\site-packages\django\core\handlers\exception.py", line 47, in inner
    response = get_response(request)
  File "F:\DevProject\master\pic-slic-master\venv\lib\site-packages\django\core\handlers\base.py", line 181, in _get_response
    response = wrapped_callback(request, *callback_args, **callback_kwargs)
  File "F:\DevProject\master\pic-slic-master\wxcloudrun\views.py", line 41, in counter
    rsp = get_count()
  File "F:\DevProject\master\pic-slic-master\wxcloudrun\views.py", line 57, in get_count
    data = Counters.objects.get(id=1)
  File "F:\DevProject\master\pic-slic-master\venv\lib\site-packages\django\db\models\manager.py", line 85, in manager_method
    return getattr(self.get_queryset(), name)(*args, **kwargs)
  File "F:\DevProject\master\pic-slic-master\venv\lib\site-packages\django\db\models\query.py", line 431, in get
    num = len(clone)
  File "F:\DevProject\master\pic-slic-master\venv\lib\site-packages\django\db\models\query.py", line 262, in __len__
    self._fetch_all()
  File "F:\DevProject\master\pic-slic-master\venv\lib\site-packages\django\db\models\query.py", line 1324, in _fetch_all
    self._result_cache = list(self._iterable_class(self))
  File "F:\DevProject\master\pic-slic-master\venv\lib\site-packages\django\db\models\query.py", line 51, in __iter__
    results = compiler.execute_sql(chunked_fetch=self.chunked_fetch, chunk_size=self.chunk_size)
  File "F:\DevProject\master\pic-slic-master\venv\lib\site-packages\django\db\models\sql\compiler.py", line 1162, in execute_sql
    sql, params = self.as_sql()
  File "F:\DevProject\master\pic-slic-master\venv\lib\site-packages\django\db\models\sql\compiler.py", line 513, in as_sql
    extra_select, order_by, group_by = self.pre_sql_setup()
  File "F:\DevProject\master\pic-slic-master\venv\lib\site-packages\django\db\models\sql\compiler.py", line 55, in pre_sql_setup
    self.setup_query()
  File "F:\DevProject\master\pic-slic-master\venv\lib\site-packages\django\db\models\sql\compiler.py", line 46, in setup_query
    self.select, self.klass_info, self.annotation_col_map = self.get_select()
  File "F:\DevProject\master\pic-slic-master\venv\lib\site-packages\django\db\models\sql\compiler.py", line 262, in get_select
    sql, params = self.compile(col)
  File "F:\DevProject\master\pic-slic-master\venv\lib\site-packages\django\db\models\sql\compiler.py", line 445, in compile
    sql, params = node.as_sql(self, self.connection)
  File "F:\DevProject\master\pic-slic-master\venv\lib\site-packages\django\db\models\expressions.py", line 835, in as_sql
    sql = '.'.join(map(compiler.quote_name_unless_alias, identifiers))
  File "F:\DevProject\master\pic-slic-master\venv\lib\site-packages\django\db\models\sql\compiler.py", line 436, in quote_name_unless_alias
    r = self.connection.ops.quote_name(name)
  File "F:\DevProject\master\pic-slic-master\venv\lib\site-packages\django\db\backends\dummy\base.py", line 20, in complain
    raise ImproperlyConfigured("settings.DATABASES is improperly configured. "
django.core.exceptions.ImproperlyConfigured: settings.DATABASES is improperly configured. Please supply the ENGINE value. Check settings documentation for more details.
[2022-12-29 20:06:57,795] [basehttp.py:161] [basehttp:log_message] [ERROR]- "GET /api/img/ HTTP/1.1" 500 130808
[2022-12-29 20:07:53,014] [autoreload.py:637] [autoreload:run_with_reloader] [INFO]- Watching for file changes with StatReloader
[2022-12-29 20:07:56,613] [log.py:224] [log:log_response] [ERROR]- Internal Server Error: /api/img/
Traceback (most recent call last):
  File "F:\DevProject\master\pic-slic-master\venv\lib\site-packages\django\core\handlers\exception.py", line 47, in inner
    response = get_response(request)
  File "F:\DevProject\master\pic-slic-master\venv\lib\site-packages\django\core\handlers\base.py", line 181, in _get_response
    response = wrapped_callback(request, *callback_args, **callback_kwargs)
TypeError: test_pro() takes 0 positional arguments but 2 were given
[2022-12-29 20:07:56,614] [basehttp.py:161] [basehttp:log_message] [ERROR]- "GET /api/img/ HTTP/1.1" 500 62898
[2022-12-29 20:09:12,834] [autoreload.py:251] [autoreload:trigger_reload] [INFO]- F:\DevProject\master\pic-slic-master\wxcloudrun\imgProcess.py changed, reloading.
[2022-12-29 20:09:13,424] [autoreload.py:637] [autoreload:run_with_reloader] [INFO]- Watching for file changes with StatReloader
[2022-12-29 20:09:18,052] [log.py:224] [log:log_response] [ERROR]- Internal Server Error: /api/img/
Traceback (most recent call last):
  File "F:\DevProject\master\pic-slic-master\venv\lib\site-packages\django\core\handlers\exception.py", line 47, in inner
    response = get_response(request)
  File "F:\DevProject\master\pic-slic-master\venv\lib\site-packages\django\core\handlers\base.py", line 181, in _get_response
    response = wrapped_callback(request, *callback_args, **callback_kwargs)
  File "F:\DevProject\master\pic-slic-master\wxcloudrun\imgProcess.py", line 180, in test_pro
    imgs = fillet_Process(imgs_read(), 15, 2)
  File "F:\DevProject\master\pic-slic-master\wxcloudrun\imgProcess.py", line 21, in imgs_read
    filenames = os.listdir(folder_path)
FileNotFoundError: [WinError 3] 系统找不到指定的路径。: './1'
[2022-12-29 20:09:18,053] [basehttp.py:161] [basehttp:log_message] [ERROR]- "GET /api/img/ HTTP/1.1" 500 70418
[2022-12-29 20:24:57,318] [autoreload.py:251] [autoreload:trigger_reload] [INFO]- F:\DevProject\master\pic-slic-master\wxcloudrun\imgProcess.py changed, reloading.
[2022-12-29 20:24:57,918] [autoreload.py:637] [autoreload:run_with_reloader] [INFO]- Watching for file changes with StatReloader
[2022-12-29 20:25:03,000] [log.py:224] [log:log_response] [ERROR]- Internal Server Error: /api/img/
Traceback (most recent call last):
  File "F:\DevProject\master\pic-slic-master\venv\lib\site-packages\django\core\handlers\exception.py", line 47, in inner
    response = get_response(request)
  File "F:\DevProject\master\pic-slic-master\venv\lib\site-packages\django\core\handlers\base.py", line 181, in _get_response
    response = wrapped_callback(request, *callback_args, **callback_kwargs)
  File "F:\DevProject\master\pic-slic-master\wxcloudrun\imgProcess.py", line 180, in test_pro
    imgs = fillet_Process(imgs_read(), 15, 2)
  File "F:\DevProject\master\pic-slic-master\wxcloudrun\imgProcess.py", line 21, in imgs_read
    filenames = os.listdir(folder_path)
FileNotFoundError: [WinError 3] 系统找不到指定的路径。: './1'
[2022-12-29 20:25:03,001] [basehttp.py:161] [basehttp:log_message] [ERROR]- "GET /api/img/ HTTP/1.1" 500 70418
[2022-12-29 20:25:10,680] [log.py:224] [log:log_response] [ERROR]- Internal Server Error: /api/img/
Traceback (most recent call last):
  File "F:\DevProject\master\pic-slic-master\venv\lib\site-packages\django\core\handlers\exception.py", line 47, in inner
    response = get_response(request)
  File "F:\DevProject\master\pic-slic-master\venv\lib\site-packages\django\core\handlers\base.py", line 181, in _get_response
    response = wrapped_callback(request, *callback_args, **callback_kwargs)
  File "F:\DevProject\master\pic-slic-master\wxcloudrun\imgProcess.py", line 180, in test_pro
    imgs = fillet_Process(imgs_read(), 15, 2)
  File "F:\DevProject\master\pic-slic-master\wxcloudrun\imgProcess.py", line 21, in imgs_read
    filenames = os.listdir(folder_path)
FileNotFoundError: [WinError 3] 系统找不到指定的路径。: './1'
[2022-12-29 20:25:10,681] [basehttp.py:161] [basehttp:log_message] [ERROR]- "GET /api/img/ HTTP/1.1" 500 70418
[2022-12-29 20:25:28,289] [autoreload.py:251] [autoreload:trigger_reload] [INFO]- F:\DevProject\master\pic-slic-master\wxcloudrun\imgProcess.py changed, reloading.
[2022-12-29 20:25:28,905] [autoreload.py:637] [autoreload:run_with_reloader] [INFO]- Watching for file changes with StatReloader
[2022-12-29 20:25:29,983] [log.py:224] [log:log_response] [ERROR]- Internal Server Error: /api/img/
Traceback (most recent call last):
  File "F:\DevProject\master\pic-slic-master\venv\lib\site-packages\django\core\handlers\exception.py", line 47, in inner
    response = get_response(request)
  File "F:\DevProject\master\pic-slic-master\venv\lib\site-packages\django\core\handlers\base.py", line 181, in _get_response
    response = wrapped_callback(request, *callback_args, **callback_kwargs)
  File "F:\DevProject\master\pic-slic-master\wxcloudrun\imgProcess.py", line 180, in test_pro
    imgs = fillet_Process(imgs_read(), 15, 2)
  File "F:\DevProject\master\pic-slic-master\wxcloudrun\imgProcess.py", line 21, in imgs_read
    filenames = os.listdir(folder_path)
FileNotFoundError: [WinError 3] 系统找不到指定的路径。: './static/1'
[2022-12-29 20:25:29,984] [basehttp.py:161] [basehttp:log_message] [ERROR]- "GET /api/img/ HTTP/1.1" 500 70453
[2022-12-29 20:27:18,544] [autoreload.py:251] [autoreload:trigger_reload] [INFO]- F:\DevProject\master\pic-slic-master\wxcloudrun\settings.py changed, reloading.
[2022-12-29 20:27:19,119] [autoreload.py:637] [autoreload:run_with_reloader] [INFO]- Watching for file changes with StatReloader
[2022-12-29 20:27:24,724] [log.py:224] [log:log_response] [ERROR]- Internal Server Error: /api/img/
Traceback (most recent call last):
  File "F:\DevProject\master\pic-slic-master\venv\lib\site-packages\django\core\handlers\exception.py", line 47, in inner
    response = get_response(request)
  File "F:\DevProject\master\pic-slic-master\venv\lib\site-packages\django\core\handlers\base.py", line 181, in _get_response
    response = wrapped_callback(request, *callback_args, **callback_kwargs)
  File "F:\DevProject\master\pic-slic-master\wxcloudrun\imgProcess.py", line 180, in test_pro
    imgs = fillet_Process(imgs_read(), 15, 2)
  File "F:\DevProject\master\pic-slic-master\wxcloudrun\imgProcess.py", line 21, in imgs_read
    filenames = os.listdir(folder_path)
FileNotFoundError: [WinError 3] 系统找不到指定的路径。: './static/1'
[2022-12-29 20:27:24,725] [basehttp.py:161] [basehttp:log_message] [ERROR]- "GET /api/img/ HTTP/1.1" 500 70521
[2022-12-29 20:30:53,976] [autoreload.py:251] [autoreload:trigger_reload] [INFO]- F:\DevProject\master\pic-slic-master\wxcloudrun\settings.py changed, reloading.
[2022-12-29 20:53:40,986] [autoreload.py:637] [autoreload:run_with_reloader] [INFO]- Watching for file changes with StatReloader
[2022-12-29 20:54:00,066] [autoreload.py:637] [autoreload:run_with_reloader] [INFO]- Watching for file changes with StatReloader
[2022-12-29 20:54:03,124] [log.py:224] [log:log_response] [WARNING]- Not Found: /
[2022-12-29 20:54:03,124] [basehttp.py:161] [basehttp:log_message] [WARNING]- "GET / HTTP/1.1" 404 2175
[2022-12-29 20:54:22,091] [basehttp.py:161] [basehttp:log_message] [INFO]- "GET /img/ HTTP/1.1" 200 1043
[2022-12-29 20:54:39,180] [log.py:224] [log:log_response] [ERROR]- Internal Server Error: /api/img/
Traceback (most recent call last):
  File "F:\DevProject\master\pic-slic-master\venv\lib\site-packages\django\core\handlers\exception.py", line 47, in inner
    response = get_response(request)
  File "F:\DevProject\master\pic-slic-master\venv\lib\site-packages\django\core\handlers\base.py", line 181, in _get_response
    response = wrapped_callback(request, *callback_args, **callback_kwargs)
  File "F:\DevProject\master\pic-slic-master\wxcloudrun\imgProcess.py", line 181, in test_pro
    imgs = fillet_Process(imgs_read(), 15, 2)
  File "F:\DevProject\master\pic-slic-master\wxcloudrun\imgProcess.py", line 22, in imgs_read
    filenames = os.listdir(folder_path)
FileNotFoundError: [WinError 3] 系统找不到指定的路径。: '/static/1'
[2022-12-29 20:54:39,181] [basehttp.py:161] [basehttp:log_message] [ERROR]- "GET /api/img/ HTTP/1.1" 500 69820
[2022-12-29 20:57:53,735] [autoreload.py:251] [autoreload:trigger_reload] [INFO]- F:\DevProject\master\pic-slic-master\wxcloudrun\settings.py changed, reloading.
[2022-12-29 20:57:54,348] [autoreload.py:637] [autoreload:run_with_reloader] [INFO]- Watching for file changes with StatReloader
[2022-12-29 20:59:08,914] [autoreload.py:251] [autoreload:trigger_reload] [INFO]- F:\DevProject\master\pic-slic-master\wxcloudrun\settings.py changed, reloading.
[2022-12-29 20:59:09,516] [autoreload.py:637] [autoreload:run_with_reloader] [INFO]- Watching for file changes with StatReloader
[2022-12-29 20:59:21,013] [autoreload.py:637] [autoreload:run_with_reloader] [INFO]- Watching for file changes with StatReloader
[2022-12-29 20:59:52,712] [autoreload.py:637] [autoreload:run_with_reloader] [INFO]- Watching for file changes with StatReloader
[2022-12-29 21:00:01,014] [log.py:224] [log:log_response] [ERROR]- Internal Server Error: /api/img/
Traceback (most recent call last):
  File "F:\DevProject\master\pic-slic-master\venv\lib\site-packages\django\core\handlers\exception.py", line 47, in inner
    response = get_response(request)
  File "F:\DevProject\master\pic-slic-master\venv\lib\site-packages\django\core\handlers\base.py", line 181, in _get_response
    response = wrapped_callback(request, *callback_args, **callback_kwargs)
  File "F:\DevProject\master\pic-slic-master\wxcloudrun\imgProcess.py", line 181, in test_pro
    imgs = fillet_Process(imgs_read(), 15, 2)
  File "F:\DevProject\master\pic-slic-master\wxcloudrun\imgProcess.py", line 22, in imgs_read
    filenames = os.listdir(folder_path)
FileNotFoundError: [WinError 3] 系统找不到指定的路径。: './1'
[2022-12-29 21:00:01,015] [basehttp.py:161] [basehttp:log_message] [ERROR]- "GET /api/img/ HTTP/1.1" 500 70477
[2022-12-29 21:03:37,946] [autoreload.py:251] [autoreload:trigger_reload] [INFO]- F:\DevProject\master\pic-slic-master\wxcloudrun\imgProcess.py changed, reloading.
[2022-12-29 21:03:38,522] [autoreload.py:637] [autoreload:run_with_reloader] [INFO]- Watching for file changes with StatReloader
[2022-12-29 21:03:45,871] [log.py:224] [log:log_response] [ERROR]- Internal Server Error: /api/img/
Traceback (most recent call last):
  File "F:\DevProject\master\pic-slic-master\venv\lib\site-packages\django\core\handlers\exception.py", line 47, in inner
    response = get_response(request)
  File "F:\DevProject\master\pic-slic-master\venv\lib\site-packages\django\core\handlers\base.py", line 181, in _get_response
    response = wrapped_callback(request, *callback_args, **callback_kwargs)
  File "F:\DevProject\master\pic-slic-master\wxcloudrun\imgProcess.py", line 181, in test_pro
    imgs = fillet_Process(imgs_read(), 15, 2)
  File "F:\DevProject\master\pic-slic-master\wxcloudrun\imgProcess.py", line 22, in imgs_read
    filenames = os.listdir(folder_path)
FileNotFoundError: [WinError 3] 系统找不到指定的路径。: '/static/1'
[2022-12-29 21:03:45,872] [basehttp.py:161] [basehttp:log_message] [ERROR]- "GET /api/img/ HTTP/1.1" 500 70507
[2022-12-29 21:13:21,229] [autoreload.py:251] [autoreload:trigger_reload] [INFO]- F:\DevProject\master\pic-slic-master\wxcloudrun\imgProcess.py changed, reloading.
[2022-12-29 21:13:21,827] [autoreload.py:637] [autoreload:run_with_reloader] [INFO]- Watching for file changes with StatReloader
[2022-12-29 21:13:41,795] [autoreload.py:251] [autoreload:trigger_reload] [INFO]- F:\DevProject\master\pic-slic-master\wxcloudrun\imgProcess.py changed, reloading.
[2022-12-29 21:13:42,403] [autoreload.py:637] [autoreload:run_with_reloader] [INFO]- Watching for file changes with StatReloader
[2022-12-29 21:14:06,445] [autoreload.py:251] [autoreload:trigger_reload] [INFO]- F:\DevProject\master\pic-slic-master\wxcloudrun\imgProcess.py changed, reloading.
[2022-12-29 21:14:07,018] [autoreload.py:637] [autoreload:run_with_reloader] [INFO]- Watching for file changes with StatReloader
[2022-12-29 21:14:26,529] [log.py:224] [log:log_response] [ERROR]- Internal Server Error: /api/img/
Traceback (most recent call last):
  File "F:\DevProject\master\pic-slic-master\venv\lib\site-packages\django\core\handlers\exception.py", line 47, in inner
    response = get_response(request)
  File "F:\DevProject\master\pic-slic-master\venv\lib\site-packages\django\core\handlers\base.py", line 188, in _get_response
    self.check_response(response, callback)
  File "F:\DevProject\master\pic-slic-master\venv\lib\site-packages\django\core\handlers\base.py", line 309, in check_response
    raise ValueError(
ValueError: The view wxcloudrun.imgProcess.test_pro didn't return an HttpResponse object. It returned None instead.
[2022-12-29 21:14:26,530] [basehttp.py:161] [basehttp:log_message] [ERROR]- "GET /api/img/ HTTP/1.1" 500 68138
[2022-12-29 21:15:27,780] [log.py:224] [log:log_response] [ERROR]- Internal Server Error: /api/img/
Traceback (most recent call last):
  File "F:\DevProject\master\pic-slic-master\venv\lib\site-packages\django\core\handlers\exception.py", line 47, in inner
    response = get_response(request)
  File "F:\DevProject\master\pic-slic-master\venv\lib\site-packages\django\core\handlers\base.py", line 188, in _get_response
    self.check_response(response, callback)
  File "F:\DevProject\master\pic-slic-master\venv\lib\site-packages\django\core\handlers\base.py", line 309, in check_response
    raise ValueError(
ValueError: The view wxcloudrun.imgProcess.test_pro didn't return an HttpResponse object. It returned None instead.
[2022-12-29 21:15:27,781] [basehttp.py:161] [basehttp:log_message] [ERROR]- "GET /api/img/ HTTP/1.1" 500 68138
[2022-12-29 21:19:06,871] [autoreload.py:251] [autoreload:trigger_reload] [INFO]- F:\DevProject\master\pic-slic-master\wxcloudrun\imgProcess.py changed, reloading.
[2022-12-29 21:19:07,511] [autoreload.py:637] [autoreload:run_with_reloader] [INFO]- Watching for file changes with StatReloader
[2022-12-29 21:19:35,668] [autoreload.py:251] [autoreload:trigger_reload] [INFO]- F:\DevProject\master\pic-slic-master\wxcloudrun\imgProcess.py changed, reloading.
[2022-12-29 21:19:36,234] [autoreload.py:637] [autoreload:run_with_reloader] [INFO]- Watching for file changes with StatReloader
[2022-12-29 21:19:53,052] [basehttp.py:161] [basehttp:log_message] [INFO]- "GET /api/img/ HTTP/1.1" 200 65
[2022-12-29 21:20:39,275] [basehttp.py:161] [basehttp:log_message] [INFO]- "GET /img/ HTTP/1.1" 200 1043
[2022-12-29 21:21:07,807] [basehttp.py:161] [basehttp:log_message] [INFO]- "GET /api/img/ HTTP/1.1" 200 65
[2022-12-29 21:22:19,973] [basehttp.py:161] [basehttp:log_message] [INFO]- "GET /img/ HTTP/1.1" 200 1044
[2022-12-29 21:37:18,894] [autoreload.py:637] [autoreload:run_with_reloader] [INFO]- Watching for file changes with StatReloader
[2022-12-29 21:37:20,684] [basehttp.py:161] [basehttp:log_message] [INFO]- "GET /img/ HTTP/1.1" 200 1108
[2022-12-29 21:37:33,986] [basehttp.py:161] [basehttp:log_message] [INFO]- "GET /api/img/ HTTP/1.1" 200 65
[2022-12-29 21:38:48,300] [autoreload.py:251] [autoreload:trigger_reload] [INFO]- F:\DevProject\master\pic-slic-master\wxcloudrun\imgProcess.py changed, reloading.
[2022-12-29 21:38:48,945] [autoreload.py:637] [autoreload:run_with_reloader] [INFO]- Watching for file changes with StatReloader
[2022-12-29 21:38:53,881] [basehttp.py:161] [basehttp:log_message] [INFO]- "GET /img/ HTTP/1.1" 200 1164
[2022-12-29 21:39:03,240] [basehttp.py:161] [basehttp:log_message] [INFO]- "GET /api/img/ HTTP/1.1" 200 65
[2022-12-29 21:47:58,770] [autoreload.py:251] [autoreload:trigger_reload] [INFO]- F:\DevProject\master\pic-slic-master\wxcloudrun\imgProcess.py changed, reloading.
[2022-12-29 21:47:59,388] [autoreload.py:637] [autoreload:run_with_reloader] [INFO]- Watching for file changes with StatReloader
[2022-12-29 21:48:17,230] [autoreload.py:251] [autoreload:trigger_reload] [INFO]- F:\DevProject\master\pic-slic-master\wxcloudrun\imgProcess.py changed, reloading.
[2022-12-29 21:48:17,811] [autoreload.py:637] [autoreload:run_with_reloader] [INFO]- Watching for file changes with StatReloader
[2022-12-29 21:48:29,226] [autoreload.py:251] [autoreload:trigger_reload] [INFO]- F:\DevProject\master\pic-slic-master\wxcloudrun\imgProcess.py changed, reloading.
[2022-12-29 21:48:29,784] [autoreload.py:637] [autoreload:run_with_reloader] [INFO]- Watching for file changes with StatReloader
[2022-12-29 21:49:10,319] [autoreload.py:251] [autoreload:trigger_reload] [INFO]- F:\DevProject\master\pic-slic-master\wxcloudrun\imgProcess.py changed, reloading.
[2022-12-29 21:49:10,888] [autoreload.py:637] [autoreload:run_with_reloader] [INFO]- Watching for file changes with StatReloader
[2022-12-29 21:49:16,577] [basehttp.py:161] [basehttp:log_message] [INFO]- "GET /img/ HTTP/1.1" 200 1164
[2022-12-29 21:49:26,022] [log.py:224] [log:log_response] [ERROR]- Internal Server Error: /api/img/
Traceback (most recent call last):
  File "F:\DevProject\master\pic-slic-master\venv\lib\site-packages\django\core\handlers\exception.py", line 47, in inner
    response = get_response(request)
  File "F:\DevProject\master\pic-slic-master\venv\lib\site-packages\django\core\handlers\base.py", line 181, in _get_response
    response = wrapped_callback(request, *callback_args, **callback_kwargs)
  File "F:\DevProject\master\pic-slic-master\wxcloudrun\imgProcess.py", line 187, in test_pro
    img_base64 = base64.b64encode(img)
  File "D:\DevTool\Python\Python310\lib\base64.py", line 58, in b64encode
    encoded = binascii.b2a_base64(s, newline=False)
TypeError: a bytes-like object is required, not 'Image'
[2022-12-29 21:49:26,023] [basehttp.py:161] [basehttp:log_message] [ERROR]- "GET /api/img/ HTTP/1.1" 500 73373
[2022-12-29 21:49:43,637] [log.py:224] [log:log_response] [ERROR]- Internal Server Error: /api/img/
Traceback (most recent call last):
  File "F:\DevProject\master\pic-slic-master\venv\lib\site-packages\django\core\handlers\exception.py", line 47, in inner
    response = get_response(request)
  File "F:\DevProject\master\pic-slic-master\venv\lib\site-packages\django\core\handlers\base.py", line 181, in _get_response
    response = wrapped_callback(request, *callback_args, **callback_kwargs)
  File "F:\DevProject\master\pic-slic-master\wxcloudrun\imgProcess.py", line 187, in test_pro
    img_base64 = base64.b64encode(img)
  File "D:\DevTool\Python\Python310\lib\base64.py", line 58, in b64encode
    encoded = binascii.b2a_base64(s, newline=False)
TypeError: a bytes-like object is required, not 'Image'
[2022-12-29 21:49:43,638] [basehttp.py:161] [basehttp:log_message] [ERROR]- "GET /api/img/ HTTP/1.1" 500 73629
[2022-12-29 21:51:44,227] [autoreload.py:251] [autoreload:trigger_reload] [INFO]- F:\DevProject\master\pic-slic-master\wxcloudrun\imgProcess.py changed, reloading.
[2022-12-29 21:51:44,818] [autoreload.py:637] [autoreload:run_with_reloader] [INFO]- Watching for file changes with StatReloader
[2022-12-29 21:51:59,452] [autoreload.py:637] [autoreload:run_with_reloader] [INFO]- Watching for file changes with StatReloader
[2022-12-29 21:52:16,878] [basehttp.py:161] [basehttp:log_message] [INFO]- "GET /api/img/ HTTP/1.1" 200 11059200
[2022-12-29 21:52:51,524] [basehttp.py:161] [basehttp:log_message] [INFO]- "GET /img/ HTTP/1.1" 200 1164
[2022-12-29 21:53:01,112] [basehttp.py:161] [basehttp:log_message] [INFO]- "GET /api/img/ HTTP/1.1" 200 11059200
[2022-12-29 22:01:02,455] [autoreload.py:637] [autoreload:run_with_reloader] [INFO]- Watching for file changes with StatReloader
[2022-12-29 22:01:06,358] [basehttp.py:161] [basehttp:log_message] [INFO]- "GET /img/ HTTP/1.1" 200 805
[2022-12-29 22:01:15,907] [basehttp.py:161] [basehttp:log_message] [INFO]- "GET /api/img HTTP/1.1" 200 11059200
[2022-12-29 22:06:53,436] [basehttp.py:161] [basehttp:log_message] [INFO]- "GET /img/ HTTP/1.1" 200 1636
[2022-12-29 22:07:19,180] [basehttp.py:161] [basehttp:log_message] [INFO]- "GET /img/ HTTP/1.1" 200 1636
[2022-12-29 22:07:44,535] [autoreload.py:637] [autoreload:run_with_reloader] [INFO]- Watching for file changes with StatReloader
[2022-12-29 22:07:47,378] [basehttp.py:161] [basehttp:log_message] [INFO]- "GET /img/ HTTP/1.1" 200 947
[2022-12-29 22:07:57,175] [basehttp.py:161] [basehttp:log_message] [INFO]- "GET /api/img HTTP/1.1" 200 11059200
[2022-12-29 22:12:37,025] [autoreload.py:637] [autoreload:run_with_reloader] [INFO]- Watching for file changes with StatReloader
[2022-12-29 22:12:42,213] [basehttp.py:161] [basehttp:log_message] [INFO]- "GET /img/ HTTP/1.1" 200 947
[2022-12-29 22:12:52,225] [basehttp.py:161] [basehttp:log_message] [INFO]- "GET /api/img HTTP/1.1" 200 11059200
[2022-12-29 22:17:04,780] [autoreload.py:251] [autoreload:trigger_reload] [INFO]- F:\DevProject\master\pic-slic-master\wxcloudrun\imgProcess.py changed, reloading.
[2022-12-29 22:17:05,383] [autoreload.py:637] [autoreload:run_with_reloader] [INFO]- Watching for file changes with StatReloader
[2022-12-29 22:17:16,672] [basehttp.py:161] [basehttp:log_message] [INFO]- "GET /img/ HTTP/1.1" 200 947
[2022-12-29 22:17:26,189] [basehttp.py:161] [basehttp:log_message] [INFO]- "GET /api/img HTTP/1.1" 200 11059200
[2022-12-29 22:18:43,225] [basehttp.py:161] [basehttp:log_message] [INFO]- "GET /img/ HTTP/1.1" 200 983
[2022-12-29 22:18:52,427] [basehttp.py:161] [basehttp:log_message] [INFO]- "GET /api/img HTTP/1.1" 200 11059200
[2022-12-29 22:23:30,298] [basehttp.py:161] [basehttp:log_message] [INFO]- "GET /img/ HTTP/1.1" 200 1057
[2022-12-29 22:23:39,528] [basehttp.py:161] [basehttp:log_message] [INFO]- "GET /api/img HTTP/1.1" 200 11059200
[2022-12-29 22:29:03,448] [basehttp.py:161] [basehttp:log_message] [INFO]- "GET /img/ HTTP/1.1" 200 1010
[2022-12-29 22:29:12,857] [basehttp.py:161] [basehttp:log_message] [INFO]- "GET /api/img HTTP/1.1" 200 11059200
[2022-12-29 22:29:27,836] [basehttp.py:161] [basehttp:log_message] [INFO]- "GET /img/ HTTP/1.1" 200 1010
[2022-12-29 22:29:37,204] [basehttp.py:161] [basehttp:log_message] [INFO]- "GET /api/img HTTP/1.1" 200 11059200
[2022-12-29 22:31:11,844] [basehttp.py:161] [basehttp:log_message] [INFO]- "GET /img/ HTTP/1.1" 200 1140
[2022-12-29 22:31:21,035] [basehttp.py:161] [basehttp:log_message] [INFO]- "GET /api/img HTTP/1.1" 200 11059200
[2022-12-29 22:32:06,479] [basehttp.py:161] [basehttp:log_message] [INFO]- "GET /img/ HTTP/1.1" 200 1167
[2022-12-29 22:32:15,893] [basehttp.py:161] [basehttp:log_message] [INFO]- "GET /api/img HTTP/1.1" 200 11059200
[2022-12-29 22:35:52,767] [autoreload.py:637] [autoreload:run_with_reloader] [INFO]- Watching for file changes with StatReloader
[2022-12-29 22:36:05,112] [basehttp.py:161] [basehttp:log_message] [INFO]- "GET /img/ HTTP/1.1" 200 1167
[2022-12-29 22:36:16,615] [log.py:224] [log:log_response] [ERROR]- Internal Server Error: /api/img
Traceback (most recent call last):
  File "F:\DevProject\master\pic-slic-master\venv\lib\site-packages\django\core\handlers\exception.py", line 47, in inner
    response = get_response(request)
  File "F:\DevProject\master\pic-slic-master\venv\lib\site-packages\django\utils\deprecation.py", line 119, in __call__
    response = self.process_response(request, response)
  File "F:\DevProject\master\pic-slic-master\venv\lib\site-packages\django\middleware\clickjacking.py", line 26, in process_response
    if response.get('X-Frame-Options') is not None:
AttributeError: 'bytes' object has no attribute 'get'
[2022-12-29 22:36:16,616] [basehttp.py:161] [basehttp:log_message] [ERROR]- "GET /api/img HTTP/1.1" 500 75355
[2022-12-29 22:38:39,161] [autoreload.py:251] [autoreload:trigger_reload] [INFO]- F:\DevProject\master\pic-slic-master\wxcloudrun\imgProcess.py changed, reloading.
[2022-12-29 22:38:39,765] [autoreload.py:637] [autoreload:run_with_reloader] [INFO]- Watching for file changes with StatReloader
[2022-12-29 22:38:42,385] [basehttp.py:161] [basehttp:log_message] [INFO]- "GET /img/ HTTP/1.1" 200 1167
[2022-12-29 22:39:01,809] [log.py:224] [log:log_response] [ERROR]- Internal Server Error: /api/img
Traceback (most recent call last):
  File "F:\DevProject\master\pic-slic-master\venv\lib\site-packages\django\core\handlers\exception.py", line 47, in inner
    response = get_response(request)
  File "F:\DevProject\master\pic-slic-master\venv\lib\site-packages\django\core\handlers\base.py", line 181, in _get_response
    response = wrapped_callback(request, *callback_args, **callback_kwargs)
  File "F:\DevProject\master\pic-slic-master\wxcloudrun\imgProcess.py", line 191, in test_pro
    response = JsonResponse({'code': 0, 'img': img_base64},
  File "F:\DevProject\master\pic-slic-master\venv\lib\site-packages\django\http\response.py", line 603, in __init__
    data = json.dumps(data, cls=encoder, **json_dumps_params)
  File "D:\DevTool\Python\Python310\lib\json\__init__.py", line 238, in dumps
    **kw).encode(obj)
  File "D:\DevTool\Python\Python310\lib\json\encoder.py", line 199, in encode
    chunks = self.iterencode(o, _one_shot=True)
  File "D:\DevTool\Python\Python310\lib\json\encoder.py", line 257, in iterencode
    return _iterencode(o, 0)
  File "F:\DevProject\master\pic-slic-master\venv\lib\site-packages\django\core\serializers\json.py", line 105, in default
    return super().default(o)
  File "D:\DevTool\Python\Python310\lib\json\encoder.py", line 179, in default
    raise TypeError(f'Object of type {o.__class__.__name__} '
TypeError: Object of type bytes is not JSON serializable
[2022-12-29 22:39:01,811] [basehttp.py:161] [basehttp:log_message] [ERROR]- "GET /api/img HTTP/1.1" 500 131976
[2022-12-29 22:39:52,876] [basehttp.py:161] [basehttp:log_message] [INFO]- "GET /img/ HTTP/1.1" 200 1162
[2022-12-29 22:40:12,499] [log.py:224] [log:log_response] [ERROR]- Internal Server Error: /api/img
Traceback (most recent call last):
  File "F:\DevProject\master\pic-slic-master\venv\lib\site-packages\django\core\handlers\exception.py", line 47, in inner
    response = get_response(request)
  File "F:\DevProject\master\pic-slic-master\venv\lib\site-packages\django\core\handlers\base.py", line 181, in _get_response
    response = wrapped_callback(request, *callback_args, **callback_kwargs)
  File "F:\DevProject\master\pic-slic-master\wxcloudrun\imgProcess.py", line 191, in test_pro
    response = JsonResponse({'code': 0, 'img': img_base64},
  File "F:\DevProject\master\pic-slic-master\venv\lib\site-packages\django\http\response.py", line 603, in __init__
    data = json.dumps(data, cls=encoder, **json_dumps_params)
  File "D:\DevTool\Python\Python310\lib\json\__init__.py", line 238, in dumps
    **kw).encode(obj)
  File "D:\DevTool\Python\Python310\lib\json\encoder.py", line 199, in encode
    chunks = self.iterencode(o, _one_shot=True)
  File "D:\DevTool\Python\Python310\lib\json\encoder.py", line 257, in iterencode
    return _iterencode(o, 0)
  File "F:\DevProject\master\pic-slic-master\venv\lib\site-packages\django\core\serializers\json.py", line 105, in default
    return super().default(o)
  File "D:\DevTool\Python\Python310\lib\json\encoder.py", line 179, in default
    raise TypeError(f'Object of type {o.__class__.__name__} '
TypeError: Object of type bytes is not JSON serializable
[2022-12-29 22:40:12,500] [basehttp.py:161] [basehttp:log_message] [ERROR]- "GET /api/img HTTP/1.1" 500 131976
[2022-12-29 22:41:08,160] [autoreload.py:251] [autoreload:trigger_reload] [INFO]- F:\DevProject\master\pic-slic-master\wxcloudrun\imgProcess.py changed, reloading.
[2022-12-29 22:41:08,746] [autoreload.py:637] [autoreload:run_with_reloader] [INFO]- Watching for file changes with StatReloader
[2022-12-29 22:42:09,779] [autoreload.py:251] [autoreload:trigger_reload] [INFO]- F:\DevProject\master\pic-slic-master\wxcloudrun\imgProcess.py changed, reloading.
[2022-12-29 22:42:10,381] [autoreload.py:637] [autoreload:run_with_reloader] [INFO]- Watching for file changes with StatReloader
[2022-12-29 22:42:14,143] [basehttp.py:161] [basehttp:log_message] [INFO]- "GET /img/ HTTP/1.1" 200 1167
[2022-12-29 22:42:23,405] [basehttp.py:161] [basehttp:log_message] [INFO]- "GET /api/img HTTP/1.1" 200 11059200
[2022-12-29 22:44:25,145] [autoreload.py:251] [autoreload:trigger_reload] [INFO]- F:\DevProject\master\pic-slic-master\wxcloudrun\imgProcess.py changed, reloading.
[2022-12-29 22:44:25,871] [autoreload.py:637] [autoreload:run_with_reloader] [INFO]- Watching for file changes with StatReloader
[2022-12-29 22:44:27,063] [basehttp.py:161] [basehttp:log_message] [INFO]- "GET /img/ HTTP/1.1" 200 1167
[2022-12-29 22:44:36,706] [basehttp.py:161] [basehttp:log_message] [INFO]- "GET /api/img HTTP/1.1" 200 11059200
[2022-12-29 22:44:59,572] [autoreload.py:251] [autoreload:trigger_reload] [INFO]- F:\DevProject\master\pic-slic-master\wxcloudrun\urls.py changed, reloading.
[2022-12-29 22:45:00,197] [autoreload.py:637] [autoreload:run_with_reloader] [INFO]- Watching for file changes with StatReloader
[2022-12-29 22:45:03,574] [basehttp.py:161] [basehttp:log_message] [INFO]- "GET /img/ HTTP/1.1" 200 1167
[2022-12-29 22:45:03,656] [log.py:224] [log:log_response] [WARNING]- Not Found: /api/img
[2022-12-29 22:45:03,657] [basehttp.py:161] [basehttp:log_message] [WARNING]- "GET /api/img HTTP/1.1" 404 2227
[2022-12-29 22:45:33,599] [autoreload.py:251] [autoreload:trigger_reload] [INFO]- F:\DevProject\master\pic-slic-master\wxcloudrun\urls.py changed, reloading.
[2022-12-29 22:45:34,209] [autoreload.py:637] [autoreload:run_with_reloader] [INFO]- Watching for file changes with StatReloader
[2022-12-29 22:45:35,539] [basehttp.py:161] [basehttp:log_message] [INFO]- "GET /img/ HTTP/1.1" 200 1167
[2022-12-29 22:45:44,930] [basehttp.py:161] [basehttp:log_message] [INFO]- "GET /api/img HTTP/1.1" 200 11059200
[2022-12-29 22:49:13,447] [basehttp.py:161] [basehttp:log_message] [INFO]- "GET /img/ HTTP/1.1" 200 1167
[2022-12-29 22:49:22,794] [basehttp.py:161] [basehttp:log_message] [INFO]- "GET /api/img HTTP/1.1" 200 11059200
[2022-12-29 23:00:12,774] [basehttp.py:161] [basehttp:log_message] [INFO]- "GET /img/ HTTP/1.1" 200 1165
[2022-12-29 23:00:22,122] [basehttp.py:161] [basehttp:log_message] [INFO]- "GET /api/img HTTP/1.1" 200 11059200
[2022-12-29 23:09:55,255] [autoreload.py:637] [autoreload:run_with_reloader] [INFO]- Watching for file changes with StatReloader
[2022-12-29 23:10:00,095] [basehttp.py:161] [basehttp:log_message] [INFO]- "GET /img/ HTTP/1.1" 200 1942
[2022-12-29 23:10:09,569] [basehttp.py:161] [basehttp:log_message] [INFO]- "GET /api/img HTTP/1.1" 200 8294400
[2022-12-29 23:18:44,011] [basehttp.py:161] [basehttp:log_message] [INFO]- "GET /img/ HTTP/1.1" 200 1489
[2022-12-29 23:18:53,339] [basehttp.py:161] [basehttp:log_message] [INFO]- "GET /api/img HTTP/1.1" 200 8294400
